INFO 2025-04-06 09:52:40,746 autoreload 668 Watching for file changes with StatReloader
INFO 2025-04-06 09:53:30,404 basehttp 212 "GET / HTTP/1.1" 200 10664
WARNING 2025-04-06 09:53:30,917 log 241 Not Found: /favicon.ico
WARNING 2025-04-06 09:53:30,918 basehttp 212 "GET /favicon.ico HTTP/1.1" 404 2115
INFO 2025-04-06 10:02:26,547 autoreload 266 /home/yly/桌面/meiduo/meiduo_mall/meiduo_mall/settings/dev.py changed, reloading.
INFO 2025-04-06 10:02:27,644 autoreload 668 Watching for file changes with StatReloader
INFO 2025-04-10 22:36:44,643 autoreload 668 Watching for file changes with StatReloader
INFO 2025-04-10 22:43:28,546 autoreload 668 Watching for file changes with StatReloader
INFO 2025-04-10 22:43:54,015 autoreload 668 Watching for file changes with StatReloader
INFO 2025-04-10 22:46:35,180 autoreload 266 /home/yly/桌面/meiduo/meiduo_mall/meiduo_mall/settings/dev.py changed, reloading.
INFO 2025-04-10 22:46:36,019 autoreload 668 Watching for file changes with StatReloader
INFO 2025-04-10 22:55:35,654 autoreload 668 Watching for file changes with StatReloader
INFO 2025-04-10 23:05:22,001 autoreload 668 Watching for file changes with StatReloader
INFO 2025-04-10 23:07:04,990 autoreload 668 Watching for file changes with StatReloader
INFO 2025-04-10 23:07:21,586 autoreload 668 Watching for file changes with StatReloader
INFO 2025-04-10 23:07:45,121 autoreload 668 Watching for file changes with StatReloader
INFO 2025-04-10 23:22:56,936 autoreload 668 Watching for file changes with StatReloader
INFO 2025-04-10 23:29:14,929 autoreload 668 Watching for file changes with StatReloader
INFO 2025-06-01 11:03:24,017 autoreload 668 Watching for file changes with StatReloader
INFO 2025-06-01 11:04:57,597 autoreload 266 /home/yly/桌面/meiduo/meiduo_mall/meiduo_mall/apps/verifications/urls.py changed, reloading.
INFO 2025-06-01 11:04:58,319 autoreload 668 Watching for file changes with StatReloader
INFO 2025-06-01 11:09:51,409 autoreload 266 /home/yly/桌面/meiduo/meiduo_mall/meiduo_mall/apps/verifications/urls.py changed, reloading.
INFO 2025-06-01 11:09:52,384 autoreload 668 Watching for file changes with StatReloader
INFO 2025-06-01 11:19:45,202 autoreload 266 /home/yly/桌面/meiduo/meiduo_mall/meiduo_mall/apps/verifications/urls.py changed, reloading.
INFO 2025-06-01 11:19:46,280 autoreload 668 Watching for file changes with StatReloader
INFO 2025-06-01 11:21:10,550 autoreload 668 Watching for file changes with StatReloader
INFO 2025-06-01 11:22:47,919 autoreload 668 Watching for file changes with StatReloader
WARNING 2025-06-01 11:22:58,177 log 241 Not Found: /
WARNING 2025-06-01 11:22:58,178 basehttp 212 "GET / HTTP/1.1" 404 2251
WARNING 2025-06-01 11:22:58,383 log 241 Not Found: /favicon.ico
WARNING 2025-06-01 11:22:58,387 basehttp 212 "GET /favicon.ico HTTP/1.1" 404 2302
INFO 2025-06-01 11:23:52,966 autoreload 266 /home/yly/桌面/meiduo/meiduo_mall/meiduo_mall/apps/verifications/urls.py changed, reloading.
INFO 2025-06-01 11:23:53,745 autoreload 668 Watching for file changes with StatReloader
WARNING 2025-06-01 11:23:59,714 log 241 Not Found: /
WARNING 2025-06-01 11:23:59,715 basehttp 212 "GET / HTTP/1.1" 404 2252
WARNING 2025-06-01 11:24:03,998 log 241 Not Found: /
WARNING 2025-06-01 11:24:04,000 basehttp 212 "GET / HTTP/1.1" 404 2252
INFO 2025-06-01 11:26:32,217 autoreload 266 /home/yly/桌面/meiduo/meiduo_mall/meiduo_mall/apps/verifications/views.py changed, reloading.
INFO 2025-06-01 11:26:33,031 autoreload 668 Watching for file changes with StatReloader
WARNING 2025-06-01 11:26:36,347 log 241 Not Found: /
WARNING 2025-06-01 11:26:36,349 basehttp 212 "GET / HTTP/1.1" 404 2252
ERROR 2025-06-01 11:27:15,999 log 241 Internal Server Error: /smscodes/15326281142
Traceback (most recent call last):
  File "/home/yly/.virtualenvs/meiduo/lib/python3.10/site-packages/asgiref/local.py", line 19, in __getattr__
    return storage_object[key]
KeyError: 'verify_codes'

During handling of the above exception, another exception occurred:

Traceback (most recent call last):
  File "/home/yly/.virtualenvs/meiduo/lib/python3.10/site-packages/django/utils/connection.py", line 58, in __getitem__
    return getattr(self._connections, alias)
  File "/home/yly/.virtualenvs/meiduo/lib/python3.10/site-packages/asgiref/local.py", line 118, in __getattr__
    return getattr(storage, key)
  File "/home/yly/.virtualenvs/meiduo/lib/python3.10/site-packages/asgiref/local.py", line 21, in __getattr__
    raise AttributeError(f"{self!r} object has no attribute {key!r}")
AttributeError: <asgiref.local._CVar object at 0x7dab518c7eb0> object has no attribute 'verify_codes'

During handling of the above exception, another exception occurred:

Traceback (most recent call last):
  File "/home/yly/.virtualenvs/meiduo/lib/python3.10/site-packages/django/core/handlers/exception.py", line 55, in inner
    response = get_response(request)
  File "/home/yly/.virtualenvs/meiduo/lib/python3.10/site-packages/django/core/handlers/base.py", line 197, in _get_response
    response = wrapped_callback(request, *callback_args, **callback_kwargs)
  File "/home/yly/.virtualenvs/meiduo/lib/python3.10/site-packages/django/views/decorators/csrf.py", line 56, in wrapper_view
    return view_func(*args, **kwargs)
  File "/home/yly/.virtualenvs/meiduo/lib/python3.10/site-packages/django/views/generic/base.py", line 104, in view
    return self.dispatch(request, *args, **kwargs)
  File "/home/yly/.virtualenvs/meiduo/lib/python3.10/site-packages/rest_framework/views.py", line 509, in dispatch
    response = self.handle_exception(exc)
  File "/home/yly/.virtualenvs/meiduo/lib/python3.10/site-packages/rest_framework/views.py", line 469, in handle_exception
    self.raise_uncaught_exception(exc)
  File "/home/yly/.virtualenvs/meiduo/lib/python3.10/site-packages/rest_framework/views.py", line 480, in raise_uncaught_exception
    raise exc
  File "/home/yly/.virtualenvs/meiduo/lib/python3.10/site-packages/rest_framework/views.py", line 506, in dispatch
    response = handler(request, *args, **kwargs)
  File "/home/yly/桌面/meiduo/meiduo_mall/meiduo_mall/apps/verifications/views.py", line 23, in get
    redis_conn = get_redis_connection('verify_codes')
  File "/home/yly/.virtualenvs/meiduo/lib/python3.10/site-packages/django_redis/__init__.py", line 12, in get_redis_connection
    cache = caches[alias]
  File "/home/yly/.virtualenvs/meiduo/lib/python3.10/site-packages/django/utils/connection.py", line 61, in __getitem__
    raise self.exception_class(f"The connection '{alias}' doesn't exist.")
django.core.cache.backends.base.InvalidCacheBackendError: The connection 'verify_codes' doesn't exist.
ERROR 2025-06-01 11:27:16,003 basehttp 212 "GET /smscodes/15326281142 HTTP/1.1" 500 122366
ERROR 2025-06-01 11:27:25,723 log 241 Internal Server Error: /smscodes/15326381142
Traceback (most recent call last):
  File "/home/yly/.virtualenvs/meiduo/lib/python3.10/site-packages/asgiref/local.py", line 19, in __getattr__
    return storage_object[key]
KeyError: 'verify_codes'

During handling of the above exception, another exception occurred:

Traceback (most recent call last):
  File "/home/yly/.virtualenvs/meiduo/lib/python3.10/site-packages/django/utils/connection.py", line 58, in __getitem__
    return getattr(self._connections, alias)
  File "/home/yly/.virtualenvs/meiduo/lib/python3.10/site-packages/asgiref/local.py", line 118, in __getattr__
    return getattr(storage, key)
  File "/home/yly/.virtualenvs/meiduo/lib/python3.10/site-packages/asgiref/local.py", line 21, in __getattr__
    raise AttributeError(f"{self!r} object has no attribute {key!r}")
AttributeError: <asgiref.local._CVar object at 0x7dab518c7eb0> object has no attribute 'verify_codes'

During handling of the above exception, another exception occurred:

Traceback (most recent call last):
  File "/home/yly/.virtualenvs/meiduo/lib/python3.10/site-packages/django/core/handlers/exception.py", line 55, in inner
    response = get_response(request)
  File "/home/yly/.virtualenvs/meiduo/lib/python3.10/site-packages/django/core/handlers/base.py", line 197, in _get_response
    response = wrapped_callback(request, *callback_args, **callback_kwargs)
  File "/home/yly/.virtualenvs/meiduo/lib/python3.10/site-packages/django/views/decorators/csrf.py", line 56, in wrapper_view
    return view_func(*args, **kwargs)
  File "/home/yly/.virtualenvs/meiduo/lib/python3.10/site-packages/django/views/generic/base.py", line 104, in view
    return self.dispatch(request, *args, **kwargs)
  File "/home/yly/.virtualenvs/meiduo/lib/python3.10/site-packages/rest_framework/views.py", line 509, in dispatch
    response = self.handle_exception(exc)
  File "/home/yly/.virtualenvs/meiduo/lib/python3.10/site-packages/rest_framework/views.py", line 469, in handle_exception
    self.raise_uncaught_exception(exc)
  File "/home/yly/.virtualenvs/meiduo/lib/python3.10/site-packages/rest_framework/views.py", line 480, in raise_uncaught_exception
    raise exc
  File "/home/yly/.virtualenvs/meiduo/lib/python3.10/site-packages/rest_framework/views.py", line 506, in dispatch
    response = handler(request, *args, **kwargs)
  File "/home/yly/桌面/meiduo/meiduo_mall/meiduo_mall/apps/verifications/views.py", line 23, in get
    redis_conn = get_redis_connection('verify_codes')
  File "/home/yly/.virtualenvs/meiduo/lib/python3.10/site-packages/django_redis/__init__.py", line 12, in get_redis_connection
    cache = caches[alias]
  File "/home/yly/.virtualenvs/meiduo/lib/python3.10/site-packages/django/utils/connection.py", line 61, in __getitem__
    raise self.exception_class(f"The connection '{alias}' doesn't exist.")
django.core.cache.backends.base.InvalidCacheBackendError: The connection 'verify_codes' doesn't exist.
ERROR 2025-06-01 11:27:25,727 basehttp 212 "GET /smscodes/15326381142 HTTP/1.1" 500 122366
INFO 2025-06-01 11:33:02,784 autoreload 668 Watching for file changes with StatReloader
WARNING 2025-06-01 11:33:08,195 log 241 Not Found: /
WARNING 2025-06-01 11:33:08,197 basehttp 212 "GET / HTTP/1.1" 404 2252
WARNING 2025-06-01 11:33:08,317 log 241 Not Found: /favicon.ico
WARNING 2025-06-01 11:33:08,318 basehttp 212 "GET /favicon.ico HTTP/1.1" 404 2303
ERROR 2025-06-01 11:34:40,024 log 241 Internal Server Error: /smscodes/15326381142
Traceback (most recent call last):
  File "/home/yly/.virtualenvs/meiduo/lib/python3.10/site-packages/asgiref/local.py", line 19, in __getattr__
    return storage_object[key]
KeyError: 'verify_codes'

During handling of the above exception, another exception occurred:

Traceback (most recent call last):
  File "/home/yly/.virtualenvs/meiduo/lib/python3.10/site-packages/django/utils/connection.py", line 58, in __getitem__
    return getattr(self._connections, alias)
  File "/home/yly/.virtualenvs/meiduo/lib/python3.10/site-packages/asgiref/local.py", line 118, in __getattr__
    return getattr(storage, key)
  File "/home/yly/.virtualenvs/meiduo/lib/python3.10/site-packages/asgiref/local.py", line 21, in __getattr__
    raise AttributeError(f"{self!r} object has no attribute {key!r}")
AttributeError: <asgiref.local._CVar object at 0x740c302c7eb0> object has no attribute 'verify_codes'

During handling of the above exception, another exception occurred:

Traceback (most recent call last):
  File "/home/yly/.virtualenvs/meiduo/lib/python3.10/site-packages/django/core/handlers/exception.py", line 55, in inner
    response = get_response(request)
  File "/home/yly/.virtualenvs/meiduo/lib/python3.10/site-packages/django/core/handlers/base.py", line 197, in _get_response
    response = wrapped_callback(request, *callback_args, **callback_kwargs)
  File "/home/yly/.virtualenvs/meiduo/lib/python3.10/site-packages/django/views/decorators/csrf.py", line 56, in wrapper_view
    return view_func(*args, **kwargs)
  File "/home/yly/.virtualenvs/meiduo/lib/python3.10/site-packages/django/views/generic/base.py", line 104, in view
    return self.dispatch(request, *args, **kwargs)
  File "/home/yly/.virtualenvs/meiduo/lib/python3.10/site-packages/rest_framework/views.py", line 509, in dispatch
    response = self.handle_exception(exc)
  File "/home/yly/.virtualenvs/meiduo/lib/python3.10/site-packages/rest_framework/views.py", line 469, in handle_exception
    self.raise_uncaught_exception(exc)
  File "/home/yly/.virtualenvs/meiduo/lib/python3.10/site-packages/rest_framework/views.py", line 480, in raise_uncaught_exception
    raise exc
  File "/home/yly/.virtualenvs/meiduo/lib/python3.10/site-packages/rest_framework/views.py", line 506, in dispatch
    response = handler(request, *args, **kwargs)
  File "/home/yly/桌面/meiduo/meiduo_mall/meiduo_mall/apps/verifications/views.py", line 23, in get
    redis_conn = get_redis_connection('verify_codes')
  File "/home/yly/.virtualenvs/meiduo/lib/python3.10/site-packages/django_redis/__init__.py", line 12, in get_redis_connection
    cache = caches[alias]
  File "/home/yly/.virtualenvs/meiduo/lib/python3.10/site-packages/django/utils/connection.py", line 61, in __getitem__
    raise self.exception_class(f"The connection '{alias}' doesn't exist.")
django.core.cache.backends.base.InvalidCacheBackendError: The connection 'verify_codes' doesn't exist.
ERROR 2025-06-01 11:34:40,026 basehttp 212 "GET /smscodes/15326381142 HTTP/1.1" 500 122342
WARNING 2025-06-01 11:34:46,295 log 241 Not Found: /smscodes/15326381142/
WARNING 2025-06-01 11:34:46,296 basehttp 212 "GET /smscodes/15326381142/ HTTP/1.1" 404 2333
WARNING 2025-06-01 11:34:52,506 log 241 Not Found: /smscodes/15326381142/
WARNING 2025-06-01 11:34:52,507 basehttp 212 "GET /smscodes/15326381142/ HTTP/1.1" 404 2333
WARNING 2025-06-01 11:34:55,287 log 241 Not Found: /smscodes/15326381142/
WARNING 2025-06-01 11:34:55,288 basehttp 212 "GET /smscodes/15326381142/ HTTP/1.1" 404 2333
INFO 2025-06-01 11:40:42,105 autoreload 266 /home/yly/桌面/meiduo/meiduo_mall/meiduo_mall/apps/verifications/views.py changed, reloading.
INFO 2025-06-01 11:40:42,986 autoreload 668 Watching for file changes with StatReloader
WARNING 2025-06-01 11:41:21,975 log 241 Not Found: /
WARNING 2025-06-01 11:41:21,983 basehttp 212 "GET / HTTP/1.1" 404 2252
WARNING 2025-06-01 11:41:22,232 log 241 Not Found: /favicon.ico
WARNING 2025-06-01 11:41:22,234 basehttp 212 "GET /favicon.ico HTTP/1.1" 404 2303
ERROR 2025-06-01 11:41:40,458 log 241 Internal Server Error: /smscodes/15326381142
Traceback (most recent call last):
  File "/home/yly/.virtualenvs/meiduo/lib/python3.10/site-packages/asgiref/local.py", line 19, in __getattr__
    return storage_object[key]
KeyError: 'verify_codes'

During handling of the above exception, another exception occurred:

Traceback (most recent call last):
  File "/home/yly/.virtualenvs/meiduo/lib/python3.10/site-packages/django/utils/connection.py", line 58, in __getitem__
    return getattr(self._connections, alias)
  File "/home/yly/.virtualenvs/meiduo/lib/python3.10/site-packages/asgiref/local.py", line 118, in __getattr__
    return getattr(storage, key)
  File "/home/yly/.virtualenvs/meiduo/lib/python3.10/site-packages/asgiref/local.py", line 21, in __getattr__
    raise AttributeError(f"{self!r} object has no attribute {key!r}")
AttributeError: <asgiref.local._CVar object at 0x775e8d7c3eb0> object has no attribute 'verify_codes'

During handling of the above exception, another exception occurred:

Traceback (most recent call last):
  File "/home/yly/.virtualenvs/meiduo/lib/python3.10/site-packages/django/core/handlers/exception.py", line 55, in inner
    response = get_response(request)
  File "/home/yly/.virtualenvs/meiduo/lib/python3.10/site-packages/django/core/handlers/base.py", line 197, in _get_response
    response = wrapped_callback(request, *callback_args, **callback_kwargs)
  File "/home/yly/.virtualenvs/meiduo/lib/python3.10/site-packages/django/views/decorators/csrf.py", line 56, in wrapper_view
    return view_func(*args, **kwargs)
  File "/home/yly/.virtualenvs/meiduo/lib/python3.10/site-packages/django/views/generic/base.py", line 104, in view
    return self.dispatch(request, *args, **kwargs)
  File "/home/yly/.virtualenvs/meiduo/lib/python3.10/site-packages/rest_framework/views.py", line 509, in dispatch
    response = self.handle_exception(exc)
  File "/home/yly/.virtualenvs/meiduo/lib/python3.10/site-packages/rest_framework/views.py", line 469, in handle_exception
    self.raise_uncaught_exception(exc)
  File "/home/yly/.virtualenvs/meiduo/lib/python3.10/site-packages/rest_framework/views.py", line 480, in raise_uncaught_exception
    raise exc
  File "/home/yly/.virtualenvs/meiduo/lib/python3.10/site-packages/rest_framework/views.py", line 506, in dispatch
    response = handler(request, *args, **kwargs)
  File "/home/yly/桌面/meiduo/meiduo_mall/meiduo_mall/apps/verifications/views.py", line 23, in get
    redis_conn = get_redis_connection('verify_codes')
  File "/home/yly/.virtualenvs/meiduo/lib/python3.10/site-packages/django_redis/__init__.py", line 12, in get_redis_connection
    cache = caches[alias]
  File "/home/yly/.virtualenvs/meiduo/lib/python3.10/site-packages/django/utils/connection.py", line 61, in __getitem__
    raise self.exception_class(f"The connection '{alias}' doesn't exist.")
django.core.cache.backends.base.InvalidCacheBackendError: The connection 'verify_codes' doesn't exist.
ERROR 2025-06-01 11:41:40,460 basehttp 212 "GET /smscodes/15326381142 HTTP/1.1" 500 122342
INFO 2025-06-01 11:56:08,896 autoreload 668 Watching for file changes with StatReloader
WARNING 2025-06-01 11:56:12,729 log 241 Not Found: /
WARNING 2025-06-01 11:56:12,730 basehttp 212 "GET / HTTP/1.1" 404 2252
WARNING 2025-06-01 11:56:12,912 log 241 Not Found: /favicon.ico
WARNING 2025-06-01 11:56:12,913 basehttp 212 "GET /favicon.ico HTTP/1.1" 404 2303
ERROR 2025-06-01 11:56:33,695 log 241 Internal Server Error: /smscodes/15326381142
Traceback (most recent call last):
  File "/home/yly/.virtualenvs/meiduo/lib/python3.10/site-packages/asgiref/local.py", line 19, in __getattr__
    return storage_object[key]
KeyError: 'verify_codes'

During handling of the above exception, another exception occurred:

Traceback (most recent call last):
  File "/home/yly/.virtualenvs/meiduo/lib/python3.10/site-packages/django/utils/connection.py", line 58, in __getitem__
    return getattr(self._connections, alias)
  File "/home/yly/.virtualenvs/meiduo/lib/python3.10/site-packages/asgiref/local.py", line 118, in __getattr__
    return getattr(storage, key)
  File "/home/yly/.virtualenvs/meiduo/lib/python3.10/site-packages/asgiref/local.py", line 21, in __getattr__
    raise AttributeError(f"{self!r} object has no attribute {key!r}")
AttributeError: <asgiref.local._CVar object at 0x70f2eacc3eb0> object has no attribute 'verify_codes'

During handling of the above exception, another exception occurred:

Traceback (most recent call last):
  File "/home/yly/.virtualenvs/meiduo/lib/python3.10/site-packages/django/core/handlers/exception.py", line 55, in inner
    response = get_response(request)
  File "/home/yly/.virtualenvs/meiduo/lib/python3.10/site-packages/django/core/handlers/base.py", line 197, in _get_response
    response = wrapped_callback(request, *callback_args, **callback_kwargs)
  File "/home/yly/.virtualenvs/meiduo/lib/python3.10/site-packages/django/views/decorators/csrf.py", line 56, in wrapper_view
    return view_func(*args, **kwargs)
  File "/home/yly/.virtualenvs/meiduo/lib/python3.10/site-packages/django/views/generic/base.py", line 104, in view
    return self.dispatch(request, *args, **kwargs)
  File "/home/yly/.virtualenvs/meiduo/lib/python3.10/site-packages/rest_framework/views.py", line 509, in dispatch
    response = self.handle_exception(exc)
  File "/home/yly/.virtualenvs/meiduo/lib/python3.10/site-packages/rest_framework/views.py", line 469, in handle_exception
    self.raise_uncaught_exception(exc)
  File "/home/yly/.virtualenvs/meiduo/lib/python3.10/site-packages/rest_framework/views.py", line 480, in raise_uncaught_exception
    raise exc
  File "/home/yly/.virtualenvs/meiduo/lib/python3.10/site-packages/rest_framework/views.py", line 506, in dispatch
    response = handler(request, *args, **kwargs)
  File "/home/yly/桌面/meiduo/meiduo_mall/meiduo_mall/apps/verifications/views.py", line 23, in get
    redis_conn = get_redis_connection('verify_codes')
  File "/home/yly/.virtualenvs/meiduo/lib/python3.10/site-packages/django_redis/__init__.py", line 12, in get_redis_connection
    cache = caches[alias]
  File "/home/yly/.virtualenvs/meiduo/lib/python3.10/site-packages/django/utils/connection.py", line 61, in __getitem__
    raise self.exception_class(f"The connection '{alias}' doesn't exist.")
django.core.cache.backends.base.InvalidCacheBackendError: The connection 'verify_codes' doesn't exist.
ERROR 2025-06-01 11:56:33,704 basehttp 212 "GET /smscodes/15326381142 HTTP/1.1" 500 122616
ERROR 2025-06-01 11:56:34,844 log 241 Internal Server Error: /smscodes/15326381142
Traceback (most recent call last):
  File "/home/yly/.virtualenvs/meiduo/lib/python3.10/site-packages/asgiref/local.py", line 19, in __getattr__
    return storage_object[key]
KeyError: 'verify_codes'

During handling of the above exception, another exception occurred:

Traceback (most recent call last):
  File "/home/yly/.virtualenvs/meiduo/lib/python3.10/site-packages/django/utils/connection.py", line 58, in __getitem__
    return getattr(self._connections, alias)
  File "/home/yly/.virtualenvs/meiduo/lib/python3.10/site-packages/asgiref/local.py", line 118, in __getattr__
    return getattr(storage, key)
  File "/home/yly/.virtualenvs/meiduo/lib/python3.10/site-packages/asgiref/local.py", line 21, in __getattr__
    raise AttributeError(f"{self!r} object has no attribute {key!r}")
AttributeError: <asgiref.local._CVar object at 0x70f2eacc3eb0> object has no attribute 'verify_codes'

During handling of the above exception, another exception occurred:

Traceback (most recent call last):
  File "/home/yly/.virtualenvs/meiduo/lib/python3.10/site-packages/django/core/handlers/exception.py", line 55, in inner
    response = get_response(request)
  File "/home/yly/.virtualenvs/meiduo/lib/python3.10/site-packages/django/core/handlers/base.py", line 197, in _get_response
    response = wrapped_callback(request, *callback_args, **callback_kwargs)
  File "/home/yly/.virtualenvs/meiduo/lib/python3.10/site-packages/django/views/decorators/csrf.py", line 56, in wrapper_view
    return view_func(*args, **kwargs)
  File "/home/yly/.virtualenvs/meiduo/lib/python3.10/site-packages/django/views/generic/base.py", line 104, in view
    return self.dispatch(request, *args, **kwargs)
  File "/home/yly/.virtualenvs/meiduo/lib/python3.10/site-packages/rest_framework/views.py", line 509, in dispatch
    response = self.handle_exception(exc)
  File "/home/yly/.virtualenvs/meiduo/lib/python3.10/site-packages/rest_framework/views.py", line 469, in handle_exception
    self.raise_uncaught_exception(exc)
  File "/home/yly/.virtualenvs/meiduo/lib/python3.10/site-packages/rest_framework/views.py", line 480, in raise_uncaught_exception
    raise exc
  File "/home/yly/.virtualenvs/meiduo/lib/python3.10/site-packages/rest_framework/views.py", line 506, in dispatch
    response = handler(request, *args, **kwargs)
  File "/home/yly/桌面/meiduo/meiduo_mall/meiduo_mall/apps/verifications/views.py", line 23, in get
    redis_conn = get_redis_connection('verify_codes')
  File "/home/yly/.virtualenvs/meiduo/lib/python3.10/site-packages/django_redis/__init__.py", line 12, in get_redis_connection
    cache = caches[alias]
  File "/home/yly/.virtualenvs/meiduo/lib/python3.10/site-packages/django/utils/connection.py", line 61, in __getitem__
    raise self.exception_class(f"The connection '{alias}' doesn't exist.")
django.core.cache.backends.base.InvalidCacheBackendError: The connection 'verify_codes' doesn't exist.
ERROR 2025-06-01 11:56:34,848 basehttp 212 "GET /smscodes/15326381142 HTTP/1.1" 500 122342
INFO 2025-06-01 12:01:22,254 autoreload 266 /home/yly/桌面/meiduo/meiduo_mall/meiduo_mall/settings/dev.py changed, reloading.
INFO 2025-06-01 12:01:23,139 autoreload 668 Watching for file changes with StatReloader
WARNING 2025-06-01 12:01:27,058 log 241 Not Found: /
WARNING 2025-06-01 12:01:27,059 basehttp 212 "GET / HTTP/1.1" 404 2252
WARNING 2025-06-01 12:01:27,253 log 241 Not Found: /favicon.ico
WARNING 2025-06-01 12:01:27,256 basehttp 212 "GET /favicon.ico HTTP/1.1" 404 2303
ERROR 2025-06-01 12:01:43,767 exceptions 25 [<verifications.views.SMSCodeView object at 0x71c16ec438e0>] Error 111 connecting to 192.168.239.128:6379. Connection refused.
ERROR 2025-06-01 12:01:43,822 log 241 Insufficient Storage: /smscodes/15326381142
ERROR 2025-06-01 12:01:43,823 basehttp 212 "GET /smscodes/15326381142 HTTP/1.1" 507 5304
ERROR 2025-06-01 12:01:44,700 exceptions 25 [<verifications.views.SMSCodeView object at 0x71c16ecbcaf0>] Error 111 connecting to 192.168.239.128:6379. Connection refused.
ERROR 2025-06-01 12:01:44,717 log 241 Insufficient Storage: /smscodes/15326381142
ERROR 2025-06-01 12:01:44,721 basehttp 212 "GET /smscodes/15326381142 HTTP/1.1" 507 5304
INFO 2025-06-01 12:01:44,846 basehttp 212 "GET /static/rest_framework/css/bootstrap-tweaks.css HTTP/1.1" 200 3385
INFO 2025-06-01 12:01:44,847 basehttp 212 "GET /static/rest_framework/css/default.css HTTP/1.1" 200 1152
INFO 2025-06-01 12:01:44,849 basehttp 212 "GET /static/rest_framework/js/jquery-3.5.1.min.js HTTP/1.1" 200 89476
INFO 2025-06-01 12:01:44,851 basehttp 212 "GET /static/rest_framework/css/bootstrap.min.css HTTP/1.1" 200 121457
INFO 2025-06-01 12:01:44,851 basehttp 212 "GET /static/rest_framework/js/ajax-form.js HTTP/1.1" 200 3597
INFO 2025-06-01 12:01:44,852 basehttp 212 "GET /static/rest_framework/css/prettify.css HTTP/1.1" 200 817
INFO 2025-06-01 12:01:44,907 basehttp 212 "GET /static/rest_framework/js/prettify-min.js HTTP/1.1" 200 13632
INFO 2025-06-01 12:01:44,910 basehttp 212 "GET /static/rest_framework/js/default.js HTTP/1.1" 200 1268
INFO 2025-06-01 12:01:44,911 basehttp 212 "GET /static/rest_framework/js/csrf.js HTTP/1.1" 200 1719
INFO 2025-06-01 12:01:44,915 basehttp 212 "GET /static/rest_framework/js/bootstrap.min.js HTTP/1.1" 200 39680
INFO 2025-06-01 12:01:44,997 basehttp 212 "GET /static/rest_framework/img/grid.png HTTP/1.1" 200 1458
